<?xml version="1.0" ?>
<!-- =================================================================================== -->
<!-- |    This document was autogenerated by xacro from ur3e_zimmer.urdf.xacro         | -->
<!-- |    EDITING THIS FILE BY HAND IS NOT RECOMMENDED                                 | -->
<!-- =================================================================================== -->
<robot name="ur3e">
  <!-- Robotiq Coupler -->
  <!--  + Height added by the coupler: 8mm -->
  <!--  + Reference frame: at the middle (4mm) -->
  <link name="world"/>
  <link name="single_base">
    <visual>
      <geometry>
        <mesh filename="package://zimmer_description/meshes/visual/gripper_body.dae"/>
      </geometry>
      <origin rpy="0 0 0.3927" xyz="0.0 0.0 0.0"/>
    </visual>
    <collision>
      <geometry>
        <mesh filename="package://zimmer_description/meshes/collision/zimmer_body.stl" scale="0.001 0.001 0.001"/>
      </geometry>
      <origin rpy="1.5707963267948966 0 0.3927" xyz="0 0 0.0"/>
    </collision>
    <inertial>
      <mass value="50"/>
      <inertia ixx="1.0" ixy="0.0" ixz="0.0" iyy="1.0" iyz="0.0" izz="1.0"/>
    </inertial>
  </link>
  <link name="single_finger_right">
    <visual>
      <geometry>
        <mesh filename="package://zimmer_description/meshes/visual/right_finger.dae"/>
      </geometry>
      <origin rpy="0 0 0.3927" xyz="0.0 0.0 0.0"/>
    </visual>
    <collision>
      <geometry>
        <mesh filename="package://zimmer_description/meshes/collision/Right_Finger.stl" scale="0.001 0.001 0.001"/>
      </geometry>
      <origin rpy="1.5707963267948966 0 0.3927" xyz="0 0 0.00"/>
    </collision>
    <inertial>
      <mass value="5"/>
      <inertia ixx="1.0" ixy="0.0" ixz="0.0" iyy="1.0" iyz="0.0" izz="1.0"/>
    </inertial>
  </link>
  <link name="single_finger_left">
    <visual>
      <geometry>
        <mesh filename="package://zimmer_description/meshes/visual/left_finger.dae"/>
      </geometry>
      <origin rpy="0 0 3.534292653589793" xyz="0.0 0.0 0.0"/>
    </visual>
    <collision>
      <geometry>
        <mesh filename="package://zimmer_description/meshes/collision/Left_Finger.stl" scale="0.001 0.001 0.001"/>
      </geometry>
      <origin rpy="1.5707963267948966 0 3.534292653589793" xyz="0.0 0.0 0.0"/>
    </collision>
    <inertial>
      <mass value="5"/>
      <inertia ixx="1.0" ixy="0.0" ixz="0.0" iyy="1.0" iyz="0.0" izz="1.0"/>
    </inertial>
  </link>
  <joint name="single_to_base" type="fixed">
    <origin rpy="0 0 0" xyz="0 0 0"/>
    <parent link="world"/>
    <child link="single_base"/>
  </joint>
  <joint name="single_right_finger_joint" type="prismatic">
    <axis xyz="0 1 0"/>
    <origin rpy="0.0 0.0 0.0" xyz="0.0 0 0"/>
    <parent link="single_base"/>
    <child link="single_finger_right"/>
    <limit effort="1000.0" lower="-0.013" upper="0.0" velocity="10"/>
  </joint>
  <joint name="single_left_finger_joint" type="prismatic">
    <mimic joint="single_right_finger_joint"/>
    <axis xyz="0 1 0"/>
    <origin rpy="0.0 0.0 3.1415926535" xyz="0.0 0 0"/>
    <parent link="single_base"/>
    <child link="single_finger_left"/>
    <limit effort="1000.0" lower="-0.013" upper="0.0" velocity="10"/>
  </joint>
  <ros2_control name="GazeboSystem" type="system">
    <hardware>
      <plugin>gazebo_ros2_control/GazeboSystem</plugin>
    </hardware>
    <joint name="single_right_finger_joint">
      <command_interface name="position"/>
      <state_interface name="position">
        <param name="initial_value">0.15</param>
      </state_interface>
      <state_interface name="velocity"/>
      <state_interface name="effort"/>
    </joint>
    <joint name="single_left_finger_joint">
      <param name="mimic">single_right_finger_joint</param>
      <param name="multiplier">1</param>
      <command_interface name="position"/>
      <state_interface name="position"/>
      <state_interface name="velocity"/>
      <state_interface name="effort"/>
    </joint>
  </ros2_control>
</robot>
